2024-05-09 13:53:28,764 -  nornir.core -     INFO -        run() - Running task 'backup_configs' with args {} on 1 hosts
2024-05-09 13:53:40,969 -  nornir.core -     INFO -        run() - Running task 'backup_configs' with args {} on 1 hosts
2024-05-09 13:53:46,743 -  nornir.core -     INFO -        run() - Running task 'backup_configs' with args {} on 2 hosts
2024-05-09 13:53:48,942 - nornir.core.task -    ERROR -      start() - Host 'AccessSW1': task 'napalm_get' failed with traceback:
Traceback (most recent call last):
  File "D:\Programs\PyCharm Community\Python PyCharm Projects\NetworkAutomationProject\.venv\Lib\site-packages\netmiko\base_connection.py", line 1137, in establish_connection
    self.remote_conn_pre.connect(**ssh_connect_params)
  File "D:\Programs\PyCharm Community\Python PyCharm Projects\NetworkAutomationProject\.venv\Lib\site-packages\paramiko\client.py", line 409, in connect
    raise NoValidConnectionsError(errors)
paramiko.ssh_exception.NoValidConnectionsError: [Errno None] Unable to connect to port 22 on 192.168.137.101

During handling of the above exception, another exception occurred:

Traceback (most recent call last):
  File "D:\Programs\PyCharm Community\Python PyCharm Projects\NetworkAutomationProject\.venv\Lib\site-packages\napalm\base\base.py", line 114, in _netmiko_open
    self._netmiko_device = ConnectHandler(
                           ^^^^^^^^^^^^^^^
  File "D:\Programs\PyCharm Community\Python PyCharm Projects\NetworkAutomationProject\.venv\Lib\site-packages\netmiko\ssh_dispatcher.py", line 399, in ConnectHandler
    return ConnectionClass(*args, **kwargs)
           ^^^^^^^^^^^^^^^^^^^^^^^^^^^^^^^^
  File "D:\Programs\PyCharm Community\Python PyCharm Projects\NetworkAutomationProject\.venv\Lib\site-packages\netmiko\base_connection.py", line 488, in __init__
    self._open()
  File "D:\Programs\PyCharm Community\Python PyCharm Projects\NetworkAutomationProject\.venv\Lib\site-packages\netmiko\base_connection.py", line 493, in _open
    self.establish_connection()
  File "D:\Programs\PyCharm Community\Python PyCharm Projects\NetworkAutomationProject\.venv\Lib\site-packages\netmiko\base_connection.py", line 1159, in establish_connection
    raise NetmikoTimeoutException(msg)
netmiko.exceptions.NetmikoTimeoutException: TCP connection to device failed.

Common causes of this problem are:
1. Incorrect hostname or IP address.
2. Wrong TCP port.
3. Intermediate firewall blocking access.

Device settings: cisco_ios 192.168.137.101:22



During handling of the above exception, another exception occurred:

Traceback (most recent call last):
  File "D:\Programs\PyCharm Community\Python PyCharm Projects\NetworkAutomationProject\.venv\Lib\site-packages\nornir\core\task.py", line 99, in start
    r = self.task(self, **self.params)
        ^^^^^^^^^^^^^^^^^^^^^^^^^^^^^^
  File "D:\Programs\PyCharm Community\Python PyCharm Projects\NetworkAutomationProject\.venv\Lib\site-packages\nornir_napalm\plugins\tasks\napalm_get.py", line 32, in napalm_get
    device = task.host.get_connection(CONNECTION_NAME, task.nornir.config)
             ^^^^^^^^^^^^^^^^^^^^^^^^^^^^^^^^^^^^^^^^^^^^^^^^^^^^^^^^^^^^^
  File "D:\Programs\PyCharm Community\Python PyCharm Projects\NetworkAutomationProject\.venv\Lib\site-packages\nornir\core\inventory.py", line 494, in get_connection
    self.open_connection(
  File "D:\Programs\PyCharm Community\Python PyCharm Projects\NetworkAutomationProject\.venv\Lib\site-packages\nornir\core\inventory.py", line 546, in open_connection
    conn_obj.open(
  File "D:\Programs\PyCharm Community\Python PyCharm Projects\NetworkAutomationProject\.venv\Lib\site-packages\nornir_napalm\plugins\connections\__init__.py", line 57, in open
    connection.open()
  File "D:\Programs\PyCharm Community\Python PyCharm Projects\NetworkAutomationProject\.venv\Lib\site-packages\napalm\ios\ios.py", line 173, in open
    self.device = self._netmiko_open(
                  ^^^^^^^^^^^^^^^^^^^
  File "D:\Programs\PyCharm Community\Python PyCharm Projects\NetworkAutomationProject\.venv\Lib\site-packages\napalm\base\base.py", line 123, in _netmiko_open
    raise ConnectionException("Cannot connect to {}".format(self.hostname))
napalm.base.exceptions.ConnectionException: Cannot connect to 192.168.137.101

2024-05-09 13:53:48,943 - nornir.core.task -    ERROR -      start() - Host 'AccessSW1': task 'backup_configs' failed with traceback:
Traceback (most recent call last):
  File "D:\Programs\PyCharm Community\Python PyCharm Projects\NetworkAutomationProject\.venv\Lib\site-packages\nornir\core\task.py", line 99, in start
    r = self.task(self, **self.params)
        ^^^^^^^^^^^^^^^^^^^^^^^^^^^^^^
  File "D:\Programs\PyCharm Community\Python PyCharm Projects\NetworkAutomationProject\NornirScripts\backupConfigScript.py", line 19, in backup_configs
    result = task.run(task=napalm_get, getters=["get_config"])           # use get_config getter
             ^^^^^^^^^^^^^^^^^^^^^^^^^^^^^^^^^^^^^^^^^^^^^^^^^
  File "D:\Programs\PyCharm Community\Python PyCharm Projects\NetworkAutomationProject\.venv\Lib\site-packages\nornir\core\task.py", line 174, in run
    raise NornirSubTaskError(task=run_task, result=r)
nornir.core.exceptions.NornirSubTaskError: Subtask: napalm_get (failed)


2024-05-09 13:54:48,487 -  nornir.core -     INFO -        run() - Running task 'backup_configs' with args {} on 2 hosts
2024-05-09 13:54:57,938 -  nornir.core -     INFO -        run() - Running task 'showdata_byfilter' with args {} on 1 hosts
2024-05-09 13:55:05,264 -  nornir.core -     INFO -        run() - Running task 'showdata_byfilter' with args {} on 1 hosts
2024-05-09 13:55:10,068 -  nornir.core -     INFO -        run() - Running task 'showdata_byfilter' with args {} on 2 hosts
2024-05-09 13:55:16,087 -  nornir.core -     INFO -        run() - Running task 'showdata_byfilter' with args {} on 2 hosts
2024-05-09 13:55:22,335 -  nornir.core -     INFO -        run() - Running task 'showdata_byfilter' with args {} on 1 hosts
2024-05-09 13:55:27,716 -  nornir.core -     INFO -        run() - Running task 'showdata_byfilter' with args {} on 1 hosts
2024-05-09 13:55:36,223 -  nornir.core -     INFO -        run() - Running task 'test_connection' with args {} on 1 hosts
2024-05-09 13:55:51,206 -  nornir.core -     INFO -        run() - Running task 'test_connection' with args {} on 1 hosts
2024-05-09 13:56:01,793 -  nornir.core -     INFO -        run() - Running task 'test_connection' with args {} on 2 hosts
2024-05-09 14:20:50,000 -  nornir.core -     INFO -        run() - Running task 'send_config' with args {} on 1 hosts
2024-05-09 14:22:25,006 -  nornir.core -     INFO -        run() - Running task 'send_config' with args {} on 1 hosts
2024-05-09 14:22:55,716 -  nornir.core -     INFO -        run() - Running task 'send_config' with args {} on 1 hosts
2024-05-09 14:23:13,453 -  nornir.core -     INFO -        run() - Running task 'send_config' with args {} on 2 hosts
2024-05-09 14:25:36,247 -  nornir.core -     INFO -        run() - Running task 'send_config' with args {} on 1 hosts
2024-05-09 14:25:50,446 -  nornir.core -     INFO -        run() - Running task 'send_config' with args {} on 1 hosts
2024-05-09 14:27:26,570 -  nornir.core -     INFO -        run() - Running task 'send_config' with args {} on 1 hosts
2024-05-09 14:27:33,025 -  nornir.core -     INFO -        run() - Running task 'send_config' with args {} on 1 hosts
2024-05-09 14:27:47,211 -  nornir.core -     INFO -        run() - Running task 'send_config' with args {} on 1 hosts
2024-05-09 14:28:09,392 -  nornir.core -     INFO -        run() - Running task 'send_config' with args {} on 2 hosts
2024-05-09 14:33:53,615 -  nornir.core -     INFO -        run() - Running task 'send_config' with args {} on 1 hosts
2024-05-09 14:34:05,331 -  nornir.core -     INFO -        run() - Running task 'send_config' with args {} on 1 hosts
2024-05-09 14:34:18,948 -  nornir.core -     INFO -        run() - Running task 'send_config' with args {} on 2 hosts
2024-05-09 14:34:30,620 -  nornir.core -     INFO -        run() - Running task 'test_connection' with args {} on 2 hosts
2024-05-09 14:34:37,111 -  nornir.core -     INFO -        run() - Running task 'test_connection' with args {} on 1 hosts
2024-05-09 15:34:01,953 -  nornir.core -     INFO -        run() - Running task 'backup_configs' with args {} on 1 hosts
2024-05-09 18:20:23,827 -  nornir.core -     INFO -        run() - Running task 'showdata_byfilter' with args {} on 1 hosts
2024-05-09 18:20:29,453 -  nornir.core -     INFO -        run() - Running task 'showdata_byfilter' with args {} on 1 hosts
2024-05-09 18:20:34,168 -  nornir.core -     INFO -        run() - Running task 'showdata_byfilter' with args {} on 2 hosts
2024-05-09 18:20:42,838 -  nornir.core -     INFO -        run() - Running task 'test_connection' with args {} on 1 hosts
2024-05-09 18:28:41,885 -  nornir.core -     INFO -        run() - Running task 'showdata_byfilter' with args {} on 1 hosts
2024-05-09 18:32:10,911 -  nornir.core -     INFO -        run() - Running task 'backup_configs' with args {} on 2 hosts
