2024-05-09 14:10:36,310 -  nornir.core -     INFO -        run() - Running task 'send_config' with args {} on 1 hosts
2024-05-09 14:16:45,574 -  nornir.core -     INFO -        run() - Running task 'send_config' with args {} on 1 hosts
2024-05-09 14:16:46,332 - nornir.core.task -    ERROR -      start() - Host 'CoreSW0': task 'netmiko_send_config' failed with traceback:
Traceback (most recent call last):
  File "D:\Programs\PyCharm Community\Python PyCharm Projects\NetworkAutomationProject\.venv\Lib\site-packages\nornir\core\task.py", line 99, in start
    r = self.task(self, **self.params)
        ^^^^^^^^^^^^^^^^^^^^^^^^^^^^^^
  File "D:\Programs\PyCharm Community\Python PyCharm Projects\NetworkAutomationProject\.venv\Lib\site-packages\nornir_netmiko\tasks\netmiko_send_config.py", line 40, in netmiko_send_config
    result = net_connect.send_config_from_file(config_file=config_file, **kwargs)
             ^^^^^^^^^^^^^^^^^^^^^^^^^^^^^^^^^^^^^^^^^^^^^^^^^^^^^^^^^^^^^^^^^^^^
  File "D:\Programs\PyCharm Community\Python PyCharm Projects\NetworkAutomationProject\.venv\Lib\site-packages\netmiko\base_connection.py", line 2168, in send_config_from_file
    with io.open(config_file, "rt", encoding="utf-8") as cfg_file:
         ^^^^^^^^^^^^^^^^^^^^^^^^^^^^^^^^^^^^^^^^^^^^
TypeError: expected str, bytes or os.PathLike object, not list

2024-05-09 14:16:46,394 - nornir.core.task -    ERROR -      start() - Host 'CoreSW0': task 'send_config' failed with traceback:
Traceback (most recent call last):
  File "D:\Programs\PyCharm Community\Python PyCharm Projects\NetworkAutomationProject\.venv\Lib\site-packages\nornir\core\task.py", line 99, in start
    r = self.task(self, **self.params)
        ^^^^^^^^^^^^^^^^^^^^^^^^^^^^^^
  File "D:\Programs\PyCharm Community\Python PyCharm Projects\NetworkAutomationProject\NornirScripts\addNewConfigScript.py", line 24, in send_config
    task.run(task=netmiko_send_config, config_file=config_commands)
  File "D:\Programs\PyCharm Community\Python PyCharm Projects\NetworkAutomationProject\.venv\Lib\site-packages\nornir\core\task.py", line 174, in run
    raise NornirSubTaskError(task=run_task, result=r)
nornir.core.exceptions.NornirSubTaskError: Subtask: netmiko_send_config (failed)


2024-05-09 14:18:29,785 -  nornir.core -     INFO -        run() - Running task 'send_config' with args {} on 1 hosts
2024-05-09 14:32:25,683 -  nornir.core -     INFO -        run() - Running task 'send_config' with args {} on 1 hosts
2024-05-09 17:01:12,562 -  nornir.core -     INFO -        run() - Running task 'send_config' with args {} on 1 hosts
2024-05-09 17:01:12,563 - nornir.core.task -    ERROR -      start() - Host 'R1': task 'send_config' failed with traceback:
Traceback (most recent call last):
  File "D:\Programs\PyCharm Community\Python PyCharm Projects\NetworkAutomationProject\.venv\Lib\site-packages\nornir\core\task.py", line 99, in start
    r = self.task(self, **self.params)
        ^^^^^^^^^^^^^^^^^^^^^^^^^^^^^^
  File "D:\Programs\PyCharm Community\Python PyCharm Projects\NetworkAutomationProject\NornirScripts\jinja2Test.py", line 15, in send_config
    host_vars = nr.inventory.hosts[f"{task.hosts}"]
                                      ^^^^^^^^^^
AttributeError: 'Task' object has no attribute 'hosts'. Did you mean: 'host'?

2024-05-09 17:01:32,183 -  nornir.core -     INFO -        run() - Running task 'send_config' with args {} on 1 hosts
